Workbook

Sheet Sheet1
A1: Employee ID | B1: Name | C1: Department | D1: Country | E1: Salary | F1: Date of Joining | G1: Performance Rating | H1: Gender | I1: Email
A2: EMP1000 | C2: Finance | E2: N/A | G2: 2 | H2: Unknown | I2: invalid_email
A3: EMP1001 | B3: Eve Adams | C3: HR | D3: Germany | E3: 54255 | F3: 42015 | G3: 1 | H3: Other | I3: user106@example.com
A4: EMP1002 | B4: Alice Brown | C4: Finance | D4: Germany | E4: 63184 | F4: 42022 | G4: 2 | I4: user176@example.com
A5: EMP1003 | B5: John Doe | C5: Sales | D5: USA | E5: 94406 | F5: 42029 | G5: 1 | H5: Male | I5: user168@example.com
A6: EMP1004 | B6: Jane Smith | C6: Sales | D6: Germany | E6: 64120 | F6: 42036 | G6: 1 | H6: Male | I6: user49@example.com
A7: EMP1005 | B7: Alice Brown | C7: IT | D7: India | E7: 78421 | F7: 42043 | G7: 2 | H7: Female | I7: user24@example.com
A8: EMP1006 | B8: Sam Wilson | C8: Sales | E8: 67721 | F8: 42050 | H8: Male | I8: user168@example.com
A9: EMP1007 | B9: Chris Lee | C9: Marketing | E9: 35364 | F9: 42057 | G9: 2 | H9: Other | I9: user26@example.com
A10: EMP1008 | B10: Alice Brown | C10: IT | D10: Germany | E10: 97881 | F10: 42064 | H10: Female | I10: user25@example.com
A11: EMP1009 | B11: Chris Lee | C11: HR | D11: UK | E11: 91846 | F11: 42071 | H11: Male | I11: user153@example.com
A12: EMP1010 | B12: Sam Wilson | C12: Finance | D12: UK | E12: 64247 | F12: 42078 | G12: 1 | H12: Female | I12: user18@example.com
A13: EMP1011 | B13: Sam Wilson | C13: IT | D13: USA | E13: 91180 | F13: 42085 | G13: 5 | H13: Male | I13: user1@example.com
A14: EMP1012 | B14: Bob Johnson | C14: Sales | E14: 96418 | F14: 42092 | G14: 5 | H14: Male | I14: user106@example.com
A15: EMP1013 | B15: Sam Wilson | D15: India | E15: 62158 | F15: 42099 | G15: 4 | I15: user180@example.com
A16: EMP1014 | B16: Jane Smith | C16: HR | E16: 59894 | F16: 42106 | G16: 2 | H16: Male | I16: user184@example.com
A17: EMP1015 | C17: IT | D17: India | E17: 92443 | F17: 42113 | G17: 3 | H17: Other | I17: user3@example.com
A18: EMP1016 | B18: Bob Johnson | D18: Germany | E18: 90271 | F18: 42120 | I18: user64@example.com
A19: EMP1017 | B19: Jane Smith | C19: Finance | D19: Australia | E19: 41341 | F19: 42127 | G19: 1 | H19: Other | I19: user38@example.com
A20: EMP1018 | B20: Alice Brown | C20: Finance | D20: UK | E20: 73602 | F20: 42134 | I20: user96@example.com
A21: EMP1019 | B21: Eve Adams | D21: India | E21: 67531 | F21: 42141 | G21: 5 | H21: Female | I21: user151@example.com
A22: EMP1020 | B22: Jane Smith | C22: HR | D22: USA | E22: N/A | F22: 42148 | G22: 2 | H22: Other | I22: user200@example.com
A23: EMP1021 | B23: Jane Smith | C23: HR | E23: 98922 | F23: 42155 | G23: 4 | I23: user77@example.com
A24: EMP1022 | B24: Eve Adams | C24: Finance | D24: India | E24: 38333 | F24: 42162 | G24: 5 | I24: user128@example.com
A25: EMP1023 | B25: Alice Brown | C25: Marketing | D25: UK | E25: 36515 | F25: 42169 | G25: 3 | H25: Male | I25: user149@example.com
A26: EMP1024 | B26: Sam Wilson | C26: Finance | E26: 91005 | F26: 42176 | G26: 1 | H26: Other | I26: user122@example.com
A27: EMP1025 | B27: Chris Lee | E27: 52272 | F27: 42183 | G27: 3 | I27: user41@example.com
A28: EMP1026 | B28: Eve Adams | C28: Sales | D28: Germany | E28: 76518 | F28: 42190 | G28: 2 | H28: Female | I28: user68@example.com
A29: EMP1027 | B29: Alice Brown | C29: IT | D29: UK | E29: 41448 | F29: 42197 | G29: 3 | H29: Other | I29: user103@example.com
A30: EMP1028 | B30: John Doe | C30: HR | D30: UK | E30: 49282 | F30: 42204 | G30: 2 | H30: Female | I30: user135@example.com
A31: EMP1029 | B31: Bob Johnson | C31: Marketing | D31: UK | E31: 92959 | F31: 42211 | G31: 5 | I31: user83@example.com
A32: EMP1030 | C32: Marketing | E32: 92259 | G32: 1 | H32: Unknown | I32: user109@example.com
A33: EMP1031 | B33: Eve Adams | C33: HR | D33: Germany | E33: 92299 | F33: 42225 | G33: 3 | H33: Male | I33: user143@example.com
A34: EMP1032 | B34: Sam Wilson | C34: HR | E34: 95586 | F34: 42232 | G34: 3 | H34: Other | I34: user190@example.com
A35: EMP1033 | B35: Chris Lee | D35: USA | E35: 95367 | F35: 42239 | H35: Male | I35: user136@example.com
A36: EMP1034 | B36: John Doe | C36: Sales | D36: Australia | E36: 79549 | F36: 42246 | G36: 3 | I36: user198@example.com
A37: EMP1035 | B37: Alice Brown | D37: UK | E37: 54463 | F37: 42253 | G37: 4 | H37: Male | I37: invalid_email
A38: EMP1036 | B38: Alice Brown | C38: IT | D38: USA | E38: 89781 | F38: 42260 | H38: Female | I38: user31@example.com
A39: EMP1037 | B39: Alice Brown | C39: HR | E39: 64796 | F39: 42267 | H39: Other | I39: user98@example.com
A40: EMP1038 | B40: John Doe | C40: Marketing | D40: UK | E40: 52093 | F40: 42274 | G40: 5 | I40: user154@example.com
...

Sheet Data Cleaning
A1: Employee ID | B1: Name | C1: Name2 | D1: Department | E1: Department2 | F1: Country | G1: Country2 | H1: Salary | I1: Salary2 | J1: Date of Joining | K1: Date of joining2 | L1: Performance Rating | M1: Performance Rating2 | N1: Gender | O1: Gender2 | P1: Email
A2: EMP1001 | B2: Eve Adams | C2: =IF(B2="","Unknown",B2) -> Eve Adams | D2: HR | E2: =IF(D2="","Marketing",D2) -> HR | F2: Germany | G2: =IF(F2="","India",F2) -> Germany | H2: 54255 | I2: =IF(H2="N/A",AVERAGEIF($E$2:$E$142,E2,$H$2:$H$142),H2) -> 54255 | J2: 42015 | K2: =IF(J2="","N/A",J2) -> 42015 | L2: 1 | M2: =IF(L2="",2,L2) -> 1 | N2: Other | O2: =IF(N2="","Female",N2) -> Other | P2: user106@example.com
A3: EMP1002 | B3: Alice Brown | C3: =IF(B3="","Unknown",B3) -> Alice Brown | D3: Finance | E3: =IF(D3="","Marketing",D3) -> Finance | F3: Germany | G3: =IF(F3="","India",F3) -> Germany | H3: 63184 | I3: =IF(H3="N/A",AVERAGEIF($E$2:$E$142,E3,$H$2:$H$142),H3) -> 63184 | J3: 42022 | K3: =IF(J3="","N/A",J3) -> 42022 | L3: 2 | M3: =IF(L3="",2,L3) -> 2 | O3: =IF(N3="","Female",N3) -> Female | P3: user176@example.com
A4: EMP1003 | B4: John Doe | C4: =IF(B4="","Unknown",B4) -> John Doe | D4: Sales | E4: =IF(D4="","Marketing",D4) -> Sales | F4: USA | G4: =IF(F4="","India",F4) -> USA | H4: 94406 | I4: =IF(H4="N/A",AVERAGEIF($E$2:$E$142,E4,$H$2:$H$142),H4) -> 94406 | J4: 42029 | K4: =IF(J4="","N/A",J4) -> 42029 | L4: 1 | M4: =IF(L4="",2,L4) -> 1 | N4: Male | O4: =IF(N4="","Female",N4) -> Male | P4: user168@example.com
A5: EMP1004 | B5: Jane Smith | C5: =IF(B5="","Unknown",B5) -> Jane Smith | D5: Sales | E5: =IF(D5="","Marketing",D5) -> Sales | F5: Germany | G5: =IF(F5="","India",F5) -> Germany | H5: 64120 | I5: =IF(H5="N/A",AVERAGEIF($E$2:$E$142,E5,$H$2:$H$142),H5) -> 64120 | J5: 42036 | K5: =IF(J5="","N/A",J5) -> 42036 | L5: 1 | M5: =IF(L5="",2,L5) -> 1 | N5: Male | O5: =IF(N5="","Female",N5) -> Male | P5: user49@example.com
A6: EMP1005 | B6: Alice Brown | C6: =IF(B6="","Unknown",B6) -> Alice Brown | D6: IT | E6: =IF(D6="","Marketing",D6) -> IT | F6: India | G6: =IF(F6="","India",F6) -> India | H6: 78421 | I6: =IF(H6="N/A",AVERAGEIF($E$2:$E$142,E6,$H$2:$H$142),H6) -> 78421 | J6: 42043 | K6: =IF(J6="","N/A",J6) -> 42043 | L6: 2 | M6: =IF(L6="",2,L6) -> 2 | N6: Female | O6: =IF(N6="","Female",N6) -> Female | P6: user24@example.com
A7: EMP1006 | B7: Sam Wilson | C7: =IF(B7="","Unknown",B7) -> Sam Wilson | D7: Sales | E7: =IF(D7="","Marketing",D7) -> Sales | G7: =IF(F7="","India",F7) -> India | H7: 67721 | I7: =IF(H7="N/A",AVERAGEIF($E$2:$E$142,E7,$H$2:$H$142),H7) -> 67721 | J7: 42050 | K7: =IF(J7="","N/A",J7) -> 42050 | M7: =IF(L7="",2,L7) -> 2 | N7: Male | O7: =IF(N7="","Female",N7) -> Male | P7: user168@example.com
A8: EMP1007 | B8: Chris Lee | C8: =IF(B8="","Unknown",B8) -> Chris Lee | D8: Marketing | E8: =IF(D8="","Marketing",D8) -> Marketing | G8: =IF(F8="","India",F8) -> India | H8: 35364 | I8: =IF(H8="N/A",AVERAGEIF($E$2:$E$142,E8,$H$2:$H$142),H8) -> 35364 | J8: 42057 | K8: =IF(J8="","N/A",J8) -> 42057 | L8: 2 | M8: =IF(L8="",2,L8) -> 2 | N8: Other | O8: =IF(N8="","Female",N8) -> Other | P8: user26@example.com
A9: EMP1008 | B9: Alice Brown | C9: =IF(B9="","Unknown",B9) -> Alice Brown | D9: IT | E9: =IF(D9="","Marketing",D9) -> IT | F9: Germany | G9: =IF(F9="","India",F9) -> Germany | H9: 97881 | I9: =IF(H9="N/A",AVERAGEIF($E$2:$E$142,E9,$H$2:$H$142),H9) -> 97881 | J9: 42064 | K9: =IF(J9="","N/A",J9) -> 42064 | M9: =IF(L9="",2,L9) -> 2 | N9: Female | O9: =IF(N9="","Female",N9) -> Female | P9: user25@example.com
A10: EMP1009 | B10: Chris Lee | C10: =IF(B10="","Unknown",B10) -> Chris Lee | D10: HR | E10: =IF(D10="","Marketing",D10) -> HR | F10: UK | G10: =IF(F10="","India",F10) -> UK | H10: 91846 | I10: =IF(H10="N/A",AVERAGEIF($E$2:$E$142,E10,$H$2:$H$142),H10) -> 91846 | J10: 42071 | K10: =IF(J10="","N/A",J10) -> 42071 | M10: =IF(L10="",2,L10) -> 2 | N10: Male | O10: =IF(N10="","Female",N10) -> Male | P10: user153@example.com
A11: EMP1010 | B11: Sam Wilson | C11: =IF(B11="","Unknown",B11) -> Sam Wilson | D11: Finance | E11: =IF(D11="","Marketing",D11) -> Finance | F11: UK | G11: =IF(F11="","India",F11) -> UK | H11: 64247 | I11: =IF(H11="N/A",AVERAGEIF($E$2:$E$142,E11,$H$2:$H$142),H11) -> 64247 | J11: 42078 | K11: =IF(J11="","N/A",J11) -> 42078 | L11: 1 | M11: =IF(L11="",2,L11) -> 1 | N11: Female | O11: =IF(N11="","Female",N11) -> Female | P11: user18@example.com
A12: EMP1011 | B12: Sam Wilson | C12: =IF(B12="","Unknown",B12) -> Sam Wilson | D12: IT | E12: =IF(D12="","Marketing",D12) -> IT | F12: USA | G12: =IF(F12="","India",F12) -> USA | H12: 91180 | I12: =IF(H12="N/A",AVERAGEIF($E$2:$E$142,E12,$H$2:$H$142),H12) -> 91180 | J12: 42085 | K12: =IF(J12="","N/A",J12) -> 42085 | L12: 5 | M12: =IF(L12="",2,L12) -> 5 | N12: Male | O12: =IF(N12="","Female",N12) -> Male | P12: user1@example.com
A13: EMP1012 | B13: Bob Johnson | C13: =IF(B13="","Unknown",B13) -> Bob Johnson | D13: Sales | E13: =IF(D13="","Marketing",D13) -> Sales | G13: =IF(F13="","India",F13) -> India | H13: 96418 | I13: =IF(H13="N/A",AVERAGEIF($E$2:$E$142,E13,$H$2:$H$142),H13) -> 96418 | J13: 42092 | K13: =IF(J13="","N/A",J13) -> 42092 | L13: 5 | M13: =IF(L13="",2,L13) -> 5 | N13: Male | O13: =IF(N13="","Female",N13) -> Male | P13: user106@example.com
A14: EMP1013 | B14: Sam Wilson | C14: =IF(B14="","Unknown",B14) -> Sam Wilson | E14: =IF(D14="","Marketing",D14) -> Marketing | F14: India | G14: =IF(F14="","India",F14) -> India | H14: 62158 | I14: =IF(H14="N/A",AVERAGEIF($E$2:$E$142,E14,$H$2:$H$142),H14) -> 62158 | J14: 42099 | K14: =IF(J14="","N/A",J14) -> 42099 | L14: 4 | M14: =IF(L14="",2,L14) -> 4 | O14: =IF(N14="","Female",N14) -> Female | P14: user180@example.com
A15: EMP1014 | B15: Jane Smith | C15: =IF(B15="","Unknown",B15) -> Jane Smith | D15: HR | E15: =IF(D15="","Marketing",D15) -> HR | G15: =IF(F15="","India",F15) -> India | H15: 59894 | I15: =IF(H15="N/A",AVERAGEIF($E$2:$E$142,E15,$H$2:$H$142),H15) -> 59894 | J15: 42106 | K15: =IF(J15="","N/A",J15) -> 42106 | L15: 2 | M15: =IF(L15="",2,L15) -> 2 | N15: Male | O15: =IF(N15="","Female",N15) -> Male | P15: user184@example.com
A16: EMP1015 | C16: =IF(B16="","Unknown",B16) -> Unknown | D16: IT | E16: =IF(D16="","Marketing",D16) -> IT | F16: India | G16: =IF(F16="","India",F16) -> India | H16: 92443 | I16: =IF(H16="N/A",AVERAGEIF($E$2:$E$142,E16,$H$2:$H$142),H16) -> 92443 | J16: 42113 | K16: =IF(J16="","N/A",J16) -> 42113 | L16: 3 | M16: =IF(L16="",2,L16) -> 3 | N16: Other | O16: =IF(N16="","Female",N16) -> Other | P16: user3@example.com
A17: EMP1016 | B17: Bob Johnson | C17: =IF(B17="","Unknown",B17) -> Bob Johnson | E17: =IF(D17="","Marketing",D17) -> Marketing | F17: Germany | G17: =IF(F17="","India",F17) -> Germany | H17: 90271 | I17: =IF(H17="N/A",AVERAGEIF($E$2:$E$142,E17,$H$2:$H$142),H17) -> 90271 | J17: 42120 | K17: =IF(J17="","N/A",J17) -> 42120 | M17: =IF(L17="",2,L17) -> 2 | O17: =IF(N17="","Female",N17) -> Female | P17: user64@example.com
A18: EMP1017 | B18: Jane Smith | C18: =IF(B18="","Unknown",B18) -> Jane Smith | D18: Finance | E18: =IF(D18="","Marketing",D18) -> Finance | F18: Australia | G18: =IF(F18="","India",F18) -> Australia | H18: 41341 | I18: =IF(H18="N/A",AVERAGEIF($E$2:$E$142,E18,$H$2:$H$142),H18) -> 41341 | J18: 42127 | K18: =IF(J18="","N/A",J18) -> 42127 | L18: 1 | M18: =IF(L18="",2,L18) -> 1 | N18: Other | O18: =IF(N18="","Female",N18) -> Other | P18: user38@example.com
A19: EMP1018 | B19: Alice Brown | C19: =IF(B19="","Unknown",B19) -> Alice Brown | D19: Finance | E19: =IF(D19="","Marketing",D19) -> Finance | F19: UK | G19: =IF(F19="","India",F19) -> UK | H19: 73602 | I19: =IF(H19="N/A",AVERAGEIF($E$2:$E$142,E19,$H$2:$H$142),H19) -> 73602 | J19: 42134 | K19: =IF(J19="","N/A",J19) -> 42134 | M19: =IF(L19="",2,L19) -> 2 | O19: =IF(N19="","Female",N19) -> Female | P19: user96@example.com
A20: EMP1019 | B20: Eve Adams | C20: =IF(B20="","Unknown",B20) -> Eve Adams | E20: =IF(D20="","Marketing",D20) -> Marketing | F20: India | G20: =IF(F20="","India",F20) -> India | H20: 67531 | I20: =IF(H20="N/A",AVERAGEIF($E$2:$E$142,E20,$H$2:$H$142),H20) -> 67531 | J20: 42141 | K20: =IF(J20="","N/A",J20) -> 42141 | L20: 5 | M20: =IF(L20="",2,L20) -> 5 | N20: Female | O20: =IF(N20="","Female",N20) -> Female | P20: user151@example.com
A21: EMP1020 | B21: Jane Smith | C21: =IF(B21="","Unknown",B21) -> Jane Smith | D21: HR | E21: =IF(D21="","Marketing",D21) -> HR | F21: USA | G21: =IF(F21="","India",F21) -> USA | H21: N/A | I21: =IF(H21="N/A",AVERAGEIF($E$2:$E$142,E21,$H$2:$H$142),H21) -> 67834.565 | J21: 42148 | K21: =IF(J21="","N/A",J21) -> 42148 | L21: 2 | M21: =IF(L21="",2,L21) -> 2 | N21: Other | O21: =IF(N21="","Female",N21) -> Other | P21: user200@example.com
A22: EMP1021 | B22: Jane Smith | C22: =IF(B22="","Unknown",B22) -> Jane Smith | D22: HR | E22: =IF(D22="","Marketing",D22) -> HR | G22: =IF(F22="","India",F22) -> India | H22: 98922 | I22: =IF(H22="N/A",AVERAGEIF($E$2:$E$142,E22,$H$2:$H$142),H22) -> 98922 | J22: 42155 | K22: =IF(J22="","N/A",J22) -> 42155 | L22: 4 | M22: =IF(L22="",2,L22) -> 4 | O22: =IF(N22="","Female",N22) -> Female | P22: user77@example.com
A23: EMP1022 | B23: Eve Adams | C23: =IF(B23="","Unknown",B23) -> Eve Adams | D23: Finance | E23: =IF(D23="","Marketing",D23) -> Finance | F23: India | G23: =IF(F23="","India",F23) -> India | H23: 38333 | I23: =IF(H23="N/A",AVERAGEIF($E$2:$E$142,E23,$H$2:$H$142),H23) -> 38333 | J23: 42162 | K23: =IF(J23="","N/A",J23) -> 42162 | L23: 5 | M23: =IF(L23="",2,L23) -> 5 | O23: =IF(N23="","Female",N23) -> Female | P23: user128@example.com
A24: EMP1023 | B24: Alice Brown | C24: =IF(B24="","Unknown",B24) -> Alice Brown | D24: Marketing | E24: =IF(D24="","Marketing",D24) -> Marketing | F24: UK | G24: =IF(F24="","India",F24) -> UK | H24: 36515 | I24: =IF(H24="N/A",AVERAGEIF($E$2:$E$142,E24,$H$2:$H$142),H24) -> 36515 | J24: 42169 | K24: =IF(J24="","N/A",J24) -> 42169 | L24: 3 | M24: =IF(L24="",2,L24) -> 3 | N24: Male | O24: =IF(N24="","Female",N24) -> Male | P24: user149@example.com
A25: EMP1024 | B25: Sam Wilson | C25: =IF(B25="","Unknown",B25) -> Sam Wilson | D25: Finance | E25: =IF(D25="","Marketing",D25) -> Finance | G25: =IF(F25="","India",F25) -> India | H25: 91005 | I25: =IF(H25="N/A",AVERAGEIF($E$2:$E$142,E25,$H$2:$H$142),H25) -> 91005 | J25: 42176 | K25: =IF(J25="","N/A",J25) -> 42176 | L25: 1 | M25: =IF(L25="",2,L25) -> 1 | N25: Other | O25: =IF(N25="","Female",N25) -> Other | P25: user122@example.com
A26: EMP1025 | B26: Chris Lee | C26: =IF(B26="","Unknown",B26) -> Chris Lee | E26: =IF(D26="","Marketing",D26) -> Marketing | G26: =IF(F26="","India",F26) -> India | H26: 52272 | I26: =IF(H26="N/A",AVERAGEIF($E$2:$E$142,E26,$H$2:$H$142),H26) -> 52272 | J26: 42183 | K26: =IF(J26="","N/A",J26) -> 42183 | L26: 3 | M26: =IF(L26="",2,L26) -> 3 | O26: =IF(N26="","Female",N26) -> Female | P26: user41@example.com
A27: EMP1026 | B27: Eve Adams | C27: =IF(B27="","Unknown",B27) -> Eve Adams | D27: Sales | E27: =IF(D27="","Marketing",D27) -> Sales | F27: Germany | G27: =IF(F27="","India",F27) -> Germany | H27: 76518 | I27: =IF(H27="N/A",AVERAGEIF($E$2:$E$142,E27,$H$2:$H$142),H27) -> 76518 | J27: 42190 | K27: =IF(J27="","N/A",J27) -> 42190 | L27: 2 | M27: =IF(L27="",2,L27) -> 2 | N27: Female | O27: =IF(N27="","Female",N27) -> Female | P27: user68@example.com
A28: EMP1027 | B28: Alice Brown | C28: =IF(B28="","Unknown",B28) -> Alice Brown | D28: IT | E28: =IF(D28="","Marketing",D28) -> IT | F28: UK | G28: =IF(F28="","India",F28) -> UK | H28: 41448 | I28: =IF(H28="N/A",AVERAGEIF($E$2:$E$142,E28,$H$2:$H$142),H28) -> 41448 | J28: 42197 | K28: =IF(J28="","N/A",J28) -> 42197 | L28: 3 | M28: =IF(L28="",2,L28) -> 3 | N28: Other | O28: =IF(N28="","Female",N28) -> Other | P28: user103@example.com
A29: EMP1028 | B29: John Doe | C29: =IF(B29="","Unknown",B29) -> John Doe | D29: HR | E29: =IF(D29="","Marketing",D29) -> HR | F29: UK | G29: =IF(F29="","India",F29) -> UK | H29: 49282 | I29: =IF(H29="N/A",AVERAGEIF($E$2:$E$142,E29,$H$2:$H$142),H29) -> 49282 | J29: 42204 | K29: =IF(J29="","N/A",J29) -> 42204 | L29: 2 | M29: =IF(L29="",2,L29) -> 2 | N29: Female | O29: =IF(N29="","Female",N29) -> Female | P29: user135@example.com
A30: EMP1029 | B30: Bob Johnson | C30: =IF(B30="","Unknown",B30) -> Bob Johnson | D30: Marketing | E30: =IF(D30="","Marketing",D30) -> Marketing | F30: UK | G30: =IF(F30="","India",F30) -> UK | H30: 92959 | I30: =IF(H30="N/A",AVERAGEIF($E$2:$E$142,E30,$H$2:$H$142),H30) -> 92959 | J30: 42211 | K30: =IF(J30="","N/A",J30) -> 42211 | L30: 5 | M30: =IF(L30="",2,L30) -> 5 | O30: =IF(N30="","Female",N30) -> Female | P30: user83@example.com
A31: EMP1031 | B31: Eve Adams | C31: =IF(B31="","Unknown",B31) -> Eve Adams | D31: HR | E31: =IF(D31="","Marketing",D31) -> HR | F31: Germany | G31: =IF(F31="","India",F31) -> Germany | H31: 92299 | I31: =IF(H31="N/A",AVERAGEIF($E$2:$E$142,E31,$H$2:$H$142),H31) -> 92299 | J31: 42225 | K31: =IF(J31="","N/A",J31) -> 42225 | L31: 3 | M31: =IF(L31="",2,L31) -> 3 | N31: Male | O31: =IF(N31="","Female",N31) -> Male | P31: user143@example.com
A32: EMP1032 | B32: Sam Wilson | C32: =IF(B32="","Unknown",B32) -> Sam Wilson | D32: HR | E32: =IF(D32="","Marketing",D32) -> HR | G32: =IF(F32="","India",F32) -> India | H32: 95586 | I32: =IF(H32="N/A",AVERAGEIF($E$2:$E$142,E32,$H$2:$H$142),H32) -> 95586 | J32: 42232 | K32: =IF(J32="","N/A",J32) -> 42232 | L32: 3 | M32: =IF(L32="",2,L32) -> 3 | N32: Other | O32: =IF(N32="","Female",N32) -> Other | P32: user190@example.com
A33: EMP1033 | B33: Chris Lee | C33: =IF(B33="","Unknown",B33) -> Chris Lee | E33: =IF(D33="","Marketing",D33) -> Marketing | F33: USA | G33: =IF(F33="","India",F33) -> USA | H33: 95367 | I33: =IF(H33="N/A",AVERAGEIF($E$2:$E$142,E33,$H$2:$H$142),H33) -> 95367 | J33: 42239 | K33: =IF(J33="","N/A",J33) -> 42239 | M33: =IF(L33="",2,L33) -> 2 | N33: Male | O33: =IF(N33="","Female",N33) -> Male | P33: user136@example.com
A34: EMP1034 | B34: John Doe | C34: =IF(B34="","Unknown",B34) -> John Doe | D34: Sales | E34: =IF(D34="","Marketing",D34) -> Sales | F34: Australia | G34: =IF(F34="","India",F34) -> Australia | H34: 79549 | I34: =IF(H34="N/A",AVERAGEIF($E$2:$E$142,E34,$H$2:$H$142),H34) -> 79549 | J34: 42246 | K34: =IF(J34="","N/A",J34) -> 42246 | L34: 3 | M34: =IF(L34="",2,L34) -> 3 | O34: =IF(N34="","Female",N34) -> Female | P34: user198@example.com
A35: EMP1035 | B35: Alice Brown | C35: =IF(B35="","Unknown",B35) -> Alice Brown | E35: =IF(D35="","Marketing",D35) -> Marketing | F35: UK | G35: =IF(F35="","India",F35) -> UK | H35: 54463 | I35: =IF(H35="N/A",AVERAGEIF($E$2:$E$142,E35,$H$2:$H$142),H35) -> 54463 | J35: 42253 | K35: =IF(J35="","N/A",J35) -> 42253 | L35: 4 | M35: =IF(L35="",2,L35) -> 4 | N35: Male | O35: =IF(N35="","Female",N35) -> Male | P35: invalid_email
A36: EMP1036 | B36: Alice Brown | C36: =IF(B36="","Unknown",B36) -> Alice Brown | D36: IT | E36: =IF(D36="","Marketing",D36) -> IT | F36: USA | G36: =IF(F36="","India",F36) -> USA | H36: 89781 | I36: =IF(H36="N/A",AVERAGEIF($E$2:$E$142,E36,$H$2:$H$142),H36) -> 89781 | J36: 42260 | K36: =IF(J36="","N/A",J36) -> 42260 | M36: =IF(L36="",2,L36) -> 2 | N36: Female | O36: =IF(N36="","Female",N36) -> Female | P36: user31@example.com
A37: EMP1037 | B37: Alice Brown | C37: =IF(B37="","Unknown",B37) -> Alice Brown | D37: HR | E37: =IF(D37="","Marketing",D37) -> HR | G37: =IF(F37="","India",F37) -> India | H37: 64796 | I37: =IF(H37="N/A",AVERAGEIF($E$2:$E$142,E37,$H$2:$H$142),H37) -> 64796 | J37: 42267 | K37: =IF(J37="","N/A",J37) -> 42267 | M37: =IF(L37="",2,L37) -> 2 | N37: Other | O37: =IF(N37="","Female",N37) -> Other | P37: user98@example.com
A38: EMP1038 | B38: John Doe | C38: =IF(B38="","Unknown",B38) -> John Doe | D38: Marketing | E38: =IF(D38="","Marketing",D38) -> Marketing | F38: UK | G38: =IF(F38="","India",F38) -> UK | H38: 52093 | I38: =IF(H38="N/A",AVERAGEIF($E$2:$E$142,E38,$H$2:$H$142),H38) -> 52093 | J38: 42274 | K38: =IF(J38="","N/A",J38) -> 42274 | L38: 5 | M38: =IF(L38="",2,L38) -> 5 | O38: =IF(N38="","Female",N38) -> Female | P38: user154@example.com
A39: EMP1039 | B39: Chris Lee | C39: =IF(B39="","Unknown",B39) -> Chris Lee | D39: HR | E39: =IF(D39="","Marketing",D39) -> HR | F39: UK | G39: =IF(F39="","India",F39) -> UK | H39: 48224 | I39: =IF(H39="N/A",AVERAGEIF($E$2:$E$142,E39,$H$2:$H$142),H39) -> 48224 | J39: 42281 | K39: =IF(J39="","N/A",J39) -> 42281 | L39: 3 | M39: =IF(L39="",2,L39) -> 3 | O39: =IF(N39="","Female",N39) -> Female | P39: user42@example.com
A40: EMP1041 | B40: Alice Brown | C40: =IF(B40="","Unknown",B40) -> Alice Brown | D40: IT | E40: =IF(D40="","Marketing",D40) -> IT | F40: Germany | G40: =IF(F40="","India",F40) -> Germany | H40: 33956 | I40: =IF(H40="N/A",AVERAGEIF($E$2:$E$142,E40,$H$2:$H$142),H40) -> 33956 | J40: 42295 | K40: =IF(J40="","N/A",J40) -> 42295 | M40: =IF(L40="",2,L40) -> 2 | O40: =IF(N40="","Female",N40) -> Female | P40: user47@example.com
...

Sheet Data_Cleaned
A1: Employee Id | B1: Name | C1: Department | D1: Country | E1: Salary | F1: Date Of Joining | G1: Performance Rating | H1: Gender | I1: Email
A2: EMP1001 | B2: =VLOOKUP(A2,'Data Cleaning'!$A$2:$P$142,3,FALSE) -> Eve Adams | C2: =VLOOKUP(A2,'Data Cleaning'!$A$2:$P$142,5,FALSE) -> HR | D2: =VLOOKUP(A2,'Data Cleaning'!$A$2:$P$142,7,FALSE) -> Germany | E2: =VLOOKUP(A2,'Data Cleaning'!$A$2:$P$142,9,FALSE) -> 54255 | F2: =VLOOKUP(A2,'Data Cleaning'!$A$2:$P$142,11,FALSE) -> 42015 | G2: =VLOOKUP(A2,'Data Cleaning'!$A$2:$P$142,13,FALSE) -> 1 | H2: =VLOOKUP(A2,'Data Cleaning'!$A$2:$P$142,15,FALSE) -> Other | I2: =VLOOKUP(A2,'Data Cleaning'!$A$2:$P$142,16,FALSE) -> user106@example.com
A3: EMP1002 | B3: =VLOOKUP(A3,'Data Cleaning'!$A$2:$P$142,3,FALSE) -> Alice Brown | C3: =VLOOKUP(A3,'Data Cleaning'!$A$2:$P$142,5,FALSE) -> Finance | D3: =VLOOKUP(A3,'Data Cleaning'!$A$2:$P$142,7,FALSE) -> Germany | E3: =VLOOKUP(A3,'Data Cleaning'!$A$2:$P$142,9,FALSE) -> 63184 | F3: =VLOOKUP(A3,'Data Cleaning'!$A$2:$P$142,11,FALSE) -> 42022 | G3: =VLOOKUP(A3,'Data Cleaning'!$A$2:$P$142,13,FALSE) -> 2 | H3: =VLOOKUP(A3,'Data Cleaning'!$A$2:$P$142,15,FALSE) -> Female | I3: =VLOOKUP(A3,'Data Cleaning'!$A$2:$P$142,16,FALSE) -> user176@example.com
A4: EMP1003 | B4: =VLOOKUP(A4,'Data Cleaning'!$A$2:$P$142,3,FALSE) -> John Doe | C4: =VLOOKUP(A4,'Data Cleaning'!$A$2:$P$142,5,FALSE) -> Sales | D4: =VLOOKUP(A4,'Data Cleaning'!$A$2:$P$142,7,FALSE) -> USA | E4: =VLOOKUP(A4,'Data Cleaning'!$A$2:$P$142,9,FALSE) -> 94406 | F4: =VLOOKUP(A4,'Data Cleaning'!$A$2:$P$142,11,FALSE) -> 42029 | G4: =VLOOKUP(A4,'Data Cleaning'!$A$2:$P$142,13,FALSE) -> 1 | H4: =VLOOKUP(A4,'Data Cleaning'!$A$2:$P$142,15,FALSE) -> Male | I4: =VLOOKUP(A4,'Data Cleaning'!$A$2:$P$142,16,FALSE) -> user168@example.com
A5: EMP1004 | B5: =VLOOKUP(A5,'Data Cleaning'!$A$2:$P$142,3,FALSE) -> Jane Smith | C5: =VLOOKUP(A5,'Data Cleaning'!$A$2:$P$142,5,FALSE) -> Sales | D5: =VLOOKUP(A5,'Data Cleaning'!$A$2:$P$142,7,FALSE) -> Germany | E5: =VLOOKUP(A5,'Data Cleaning'!$A$2:$P$142,9,FALSE) -> 64120 | F5: =VLOOKUP(A5,'Data Cleaning'!$A$2:$P$142,11,FALSE) -> 42036 | G5: =VLOOKUP(A5,'Data Cleaning'!$A$2:$P$142,13,FALSE) -> 1 | H5: =VLOOKUP(A5,'Data Cleaning'!$A$2:$P$142,15,FALSE) -> Male | I5: =VLOOKUP(A5,'Data Cleaning'!$A$2:$P$142,16,FALSE) -> user49@example.com
A6: EMP1005 | B6: =VLOOKUP(A6,'Data Cleaning'!$A$2:$P$142,3,FALSE) -> Alice Brown | C6: =VLOOKUP(A6,'Data Cleaning'!$A$2:$P$142,5,FALSE) -> IT | D6: =VLOOKUP(A6,'Data Cleaning'!$A$2:$P$142,7,FALSE) -> India | E6: =VLOOKUP(A6,'Data Cleaning'!$A$2:$P$142,9,FALSE) -> 78421 | F6: =VLOOKUP(A6,'Data Cleaning'!$A$2:$P$142,11,FALSE) -> 42043 | G6: =VLOOKUP(A6,'Data Cleaning'!$A$2:$P$142,13,FALSE) -> 2 | H6: =VLOOKUP(A6,'Data Cleaning'!$A$2:$P$142,15,FALSE) -> Female | I6: =VLOOKUP(A6,'Data Cleaning'!$A$2:$P$142,16,FALSE) -> user24@example.com
A7: EMP1006 | B7: =VLOOKUP(A7,'Data Cleaning'!$A$2:$P$142,3,FALSE) -> Sam Wilson | C7: =VLOOKUP(A7,'Data Cleaning'!$A$2:$P$142,5,FALSE) -> Sales | D7: =VLOOKUP(A7,'Data Cleaning'!$A$2:$P$142,7,FALSE) -> India | E7: =VLOOKUP(A7,'Data Cleaning'!$A$2:$P$142,9,FALSE) -> 67721 | F7: =VLOOKUP(A7,'Data Cleaning'!$A$2:$P$142,11,FALSE) -> 42050 | G7: =VLOOKUP(A7,'Data Cleaning'!$A$2:$P$142,13,FALSE) -> 2 | H7: =VLOOKUP(A7,'Data Cleaning'!$A$2:$P$142,15,FALSE) -> Male | I7: =VLOOKUP(A7,'Data Cleaning'!$A$2:$P$142,16,FALSE) -> user168@example.com
A8: EMP1007 | B8: =VLOOKUP(A8,'Data Cleaning'!$A$2:$P$142,3,FALSE) -> Chris Lee | C8: =VLOOKUP(A8,'Data Cleaning'!$A$2:$P$142,5,FALSE) -> Marketing | D8: =VLOOKUP(A8,'Data Cleaning'!$A$2:$P$142,7,FALSE) -> India | E8: =VLOOKUP(A8,'Data Cleaning'!$A$2:$P$142,9,FALSE) -> 35364 | F8: =VLOOKUP(A8,'Data Cleaning'!$A$2:$P$142,11,FALSE) -> 42057 | G8: =VLOOKUP(A8,'Data Cleaning'!$A$2:$P$142,13,FALSE) -> 2 | H8: =VLOOKUP(A8,'Data Cleaning'!$A$2:$P$142,15,FALSE) -> Other | I8: =VLOOKUP(A8,'Data Cleaning'!$A$2:$P$142,16,FALSE) -> user26@example.com
A9: EMP1008 | B9: =VLOOKUP(A9,'Data Cleaning'!$A$2:$P$142,3,FALSE) -> Alice Brown | C9: =VLOOKUP(A9,'Data Cleaning'!$A$2:$P$142,5,FALSE) -> IT | D9: =VLOOKUP(A9,'Data Cleaning'!$A$2:$P$142,7,FALSE) -> Germany | E9: =VLOOKUP(A9,'Data Cleaning'!$A$2:$P$142,9,FALSE) -> 97881 | F9: =VLOOKUP(A9,'Data Cleaning'!$A$2:$P$142,11,FALSE) -> 42064 | G9: =VLOOKUP(A9,'Data Cleaning'!$A$2:$P$142,13,FALSE) -> 2 | H9: =VLOOKUP(A9,'Data Cleaning'!$A$2:$P$142,15,FALSE) -> Female | I9: =VLOOKUP(A9,'Data Cleaning'!$A$2:$P$142,16,FALSE) -> user25@example.com
A10: EMP1009 | B10: =VLOOKUP(A10,'Data Cleaning'!$A$2:$P$142,3,FALSE) -> Chris Lee | C10: =VLOOKUP(A10,'Data Cleaning'!$A$2:$P$142,5,FALSE) -> HR | D10: =VLOOKUP(A10,'Data Cleaning'!$A$2:$P$142,7,FALSE) -> UK | E10: =VLOOKUP(A10,'Data Cleaning'!$A$2:$P$142,9,FALSE) -> 91846 | F10: =VLOOKUP(A10,'Data Cleaning'!$A$2:$P$142,11,FALSE) -> 42071 | G10: =VLOOKUP(A10,'Data Cleaning'!$A$2:$P$142,13,FALSE) -> 2 | H10: =VLOOKUP(A10,'Data Cleaning'!$A$2:$P$142,15,FALSE) -> Male | I10: =VLOOKUP(A10,'Data Cleaning'!$A$2:$P$142,16,FALSE) -> user153@example.com
A11: EMP1010 | B11: =VLOOKUP(A11,'Data Cleaning'!$A$2:$P$142,3,FALSE) -> Sam Wilson | C11: =VLOOKUP(A11,'Data Cleaning'!$A$2:$P$142,5,FALSE) -> Finance | D11: =VLOOKUP(A11,'Data Cleaning'!$A$2:$P$142,7,FALSE) -> UK | E11: =VLOOKUP(A11,'Data Cleaning'!$A$2:$P$142,9,FALSE) -> 64247 | F11: =VLOOKUP(A11,'Data Cleaning'!$A$2:$P$142,11,FALSE) -> 42078 | G11: =VLOOKUP(A11,'Data Cleaning'!$A$2:$P$142,13,FALSE) -> 1 | H11: =VLOOKUP(A11,'Data Cleaning'!$A$2:$P$142,15,FALSE) -> Female | I11: =VLOOKUP(A11,'Data Cleaning'!$A$2:$P$142,16,FALSE) -> user18@example.com
A12: EMP1011 | B12: =VLOOKUP(A12,'Data Cleaning'!$A$2:$P$142,3,FALSE) -> Sam Wilson | C12: =VLOOKUP(A12,'Data Cleaning'!$A$2:$P$142,5,FALSE) -> IT | D12: =VLOOKUP(A12,'Data Cleaning'!$A$2:$P$142,7,FALSE) -> USA | E12: =VLOOKUP(A12,'Data Cleaning'!$A$2:$P$142,9,FALSE) -> 91180 | F12: =VLOOKUP(A12,'Data Cleaning'!$A$2:$P$142,11,FALSE) -> 42085 | G12: =VLOOKUP(A12,'Data Cleaning'!$A$2:$P$142,13,FALSE) -> 5 | H12: =VLOOKUP(A12,'Data Cleaning'!$A$2:$P$142,15,FALSE) -> Male | I12: =VLOOKUP(A12,'Data Cleaning'!$A$2:$P$142,16,FALSE) -> user1@example.com
A13: EMP1012 | B13: =VLOOKUP(A13,'Data Cleaning'!$A$2:$P$142,3,FALSE) -> Bob Johnson | C13: =VLOOKUP(A13,'Data Cleaning'!$A$2:$P$142,5,FALSE) -> Sales | D13: =VLOOKUP(A13,'Data Cleaning'!$A$2:$P$142,7,FALSE) -> India | E13: =VLOOKUP(A13,'Data Cleaning'!$A$2:$P$142,9,FALSE) -> 96418 | F13: =VLOOKUP(A13,'Data Cleaning'!$A$2:$P$142,11,FALSE) -> 42092 | G13: =VLOOKUP(A13,'Data Cleaning'!$A$2:$P$142,13,FALSE) -> 5 | H13: =VLOOKUP(A13,'Data Cleaning'!$A$2:$P$142,15,FALSE) -> Male | I13: =VLOOKUP(A13,'Data Cleaning'!$A$2:$P$142,16,FALSE) -> user106@example.com
... A142: EMP1149 | B142: =VLOOKUP(A142,'Data Cleaning'!$A$2:$P$142,3,FALSE) -> Sam Wilson | C142: =VLOOKUP(A142,'Data Cleaning'!$A$2:$P$142,5,FALSE) -> Marketing | D142: =VLOOKUP(A142,'Data Cleaning'!$A$2:$P$142,7,FALSE) -> India | E142: =VLOOKUP(A142,'Data Cleaning'!$A$2:$P$142,9,FALSE) -> 98475 | F142: =VLOOKUP(A142,'Data Cleaning'!$A$2:$P$142,11,FALSE) -> 43051 | G142: =VLOOKUP(A142,'Data Cleaning'!$A$2:$P$142,13,FALSE) -> 5 | H142: =VLOOKUP(A142,'Data Cleaning'!$A$2:$P$142,15,FALSE) -> Other | I142: =VLOOKUP(A142,'Data Cleaning'!$A$2:$P$142,16,FALSE) -> user30@example.com
