Workbook

Sheet Sheet1
A1: Employee ID | B1: Name | C1: Department | D1: Country | E1: Salary | F1: Date of Joining | G1: Performance Rating | H1: Gender | I1: Email
A2: EMP1000 | C2: Finance | E2: N/A | G2: 2 | H2: Unknown | I2: invalid_email
A3: EMP1001 | B3: Eve Adams | C3: HR | D3: Germany | E3: 54255 | F3: 42015 | G3: 1 | H3: Other | I3: user106@example.com
A4: EMP1002 | B4: Alice Brown | C4: Finance | D4: Germany | E4: 63184 | F4: 42022 | G4: 2 | I4: user176@example.com
A5: EMP1003 | B5: John Doe | C5: Sales | D5: USA | E5: 94406 | F5: 42029 | G5: 1 | H5: Male | I5: user168@example.com
A6: EMP1004 | B6: Jane Smith | C6: Sales | D6: Germany | E6: 64120 | F6: 42036 | G6: 1 | H6: Male | I6: user49@example.com
A7: EMP1005 | B7: Alice Brown | C7: IT | D7: India | E7: 78421 | F7: 42043 | G7: 2 | H7: Female | I7: user24@example.com
A8: EMP1006 | B8: Sam Wilson | C8: Sales | E8: 67721 | F8: 42050 | H8: Male | I8: user168@example.com
A9: EMP1007 | B9: Chris Lee | C9: Marketing | E9: 35364 | F9: 42057 | G9: 2 | H9: Other | I9: user26@example.com
A10: EMP1008 | B10: Alice Brown | C10: IT | D10: Germany | E10: 97881 | F10: 42064 | H10: Female | I10: user25@example.com
A11: EMP1009 | B11: Chris Lee | C11: HR | D11: UK | E11: 91846 | F11: 42071 | H11: Male | I11: user153@example.com
A12: EMP1010 | B12: Sam Wilson | C12: Finance | D12: UK | E12: 64247 | F12: 42078 | G12: 1 | H12: Female | I12: user18@example.com
A13: EMP1011 | B13: Sam Wilson | C13: IT | D13: USA | E13: 91180 | F13: 42085 | G13: 5 | H13: Male | I13: user1@example.com
A14: EMP1012 | B14: Bob Johnson | C14: Sales | E14: 96418 | F14: 42092 | G14: 5 | H14: Male | I14: user106@example.com
A15: EMP1013 | B15: Sam Wilson | D15: India | E15: 62158 | F15: 42099 | G15: 4 | I15: user180@example.com
A16: EMP1014 | B16: Jane Smith | C16: HR | E16: 59894 | F16: 42106 | G16: 2 | H16: Male | I16: user184@example.com
A17: EMP1015 | C17: IT | D17: India | E17: 92443 | F17: 42113 | G17: 3 | H17: Other | I17: user3@example.com
A18: EMP1016 | B18: Bob Johnson | D18: Germany | E18: 90271 | F18: 42120 | I18: user64@example.com
A19: EMP1017 | B19: Jane Smith | C19: Finance | D19: Australia | E19: 41341 | F19: 42127 | G19: 1 | H19: Other | I19: user38@example.com
A20: EMP1018 | B20: Alice Brown | C20: Finance | D20: UK | E20: 73602 | F20: 42134 | I20: user96@example.com
A21: EMP1019 | B21: Eve Adams | D21: India | E21: 67531 | F21: 42141 | G21: 5 | H21: Female | I21: user151@example.com
A22: EMP1020 | B22: Jane Smith | C22: HR | D22: USA | E22: N/A | F22: 42148 | G22: 2 | H22: Other | I22: user200@example.com
A23: EMP1021 | B23: Jane Smith | C23: HR | E23: 98922 | F23: 42155 | G23: 4 | I23: user77@example.com
A24: EMP1022 | B24: Eve Adams | C24: Finance | D24: India | E24: 38333 | F24: 42162 | G24: 5 | I24: user128@example.com
A25: EMP1023 | B25: Alice Brown | C25: Marketing | D25: UK | E25: 36515 | F25: 42169 | G25: 3 | H25: Male | I25: user149@example.com
A26: EMP1024 | B26: Sam Wilson | C26: Finance | E26: 91005 | F26: 42176 | G26: 1 | H26: Other | I26: user122@example.com
A27: EMP1025 | B27: Chris Lee | E27: 52272 | F27: 42183 | G27: 3 | I27: user41@example.com
A28: EMP1026 | B28: Eve Adams | C28: Sales | D28: Germany | E28: 76518 | F28: 42190 | G28: 2 | H28: Female | I28: user68@example.com
A29: EMP1027 | B29: Alice Brown | C29: IT | D29: UK | E29: 41448 | F29: 42197 | G29: 3 | H29: Other | I29: user103@example.com
A30: EMP1028 | B30: John Doe | C30: HR | D30: UK | E30: 49282 | F30: 42204 | G30: 2 | H30: Female | I30: user135@example.com
A31: EMP1029 | B31: Bob Johnson | C31: Marketing | D31: UK | E31: 92959 | F31: 42211 | G31: 5 | I31: user83@example.com
A32: EMP1030 | C32: Marketing | E32: 92259 | G32: 1 | H32: Unknown | I32: user109@example.com
A33: EMP1031 | B33: Eve Adams | C33: HR | D33: Germany | E33: 92299 | F33: 42225 | G33: 3 | H33: Male | I33: user143@example.com
A34: EMP1032 | B34: Sam Wilson | C34: HR | E34: 95586 | F34: 42232 | G34: 3 | H34: Other | I34: user190@example.com
A35: EMP1033 | B35: Chris Lee | D35: USA | E35: 95367 | F35: 42239 | H35: Male | I35: user136@example.com
A36: EMP1034 | B36: John Doe | C36: Sales | D36: Australia | E36: 79549 | F36: 42246 | G36: 3 | I36: user198@example.com
A37: EMP1035 | B37: Alice Brown | D37: UK | E37: 54463 | F37: 42253 | G37: 4 | H37: Male | I37: invalid_email
A38: EMP1036 | B38: Alice Brown | C38: IT | D38: USA | E38: 89781 | F38: 42260 | H38: Female | I38: user31@example.com
A39: EMP1037 | B39: Alice Brown | C39: HR | E39: 64796 | F39: 42267 | H39: Other | I39: user98@example.com
A40: EMP1038 | B40: John Doe | C40: Marketing | D40: UK | E40: 52093 | F40: 42274 | G40: 5 | I40: user154@example.com
...

Sheet Cleaned
A1: Employee Id | B1: Name | C1: Department | D1: Country | E1: Salary | F1: Date Of Joining | G1: Performance Rating | H1: Gender | I1: Email
A2: EMP1001 | B2: Eve Adams | C2: HR | D2: Germany | E2: 54255 | F2: 42015 | G2: 1 | H2: Other | I2: user106@example.com
A3: EMP1002 | B3: Alice Brown | C3: Finance | D3: Germany | E3: 63184 | F3: 42022 | G3: 2 | H3: Female | I3: user176@example.com
A4: EMP1003 | B4: John Doe | C4: Sales | D4: USA | E4: 94406 | F4: 42029 | G4: 1 | H4: Male | I4: user168@example.com
A5: EMP1004 | B5: Jane Smith | C5: Sales | D5: Germany | E5: 64120 | F5: 42036 | G5: 1 | H5: Male | I5: user49@example.com
A6: EMP1005 | B6: Alice Brown | C6: IT | D6: India | E6: 78421 | F6: 42043 | G6: 2 | H6: Female | I6: user24@example.com
A7: EMP1006 | B7: Sam Wilson | C7: Sales | D7: India | E7: 67721 | F7: 42050 | G7: 2 | H7: Male | I7: user168@example.com
A8: EMP1007 | B8: Chris Lee | C8: Marketing | D8: India | E8: 35364 | F8: 42057 | G8: 2 | H8: Other | I8: user26@example.com
A9: EMP1008 | B9: Alice Brown | C9: IT | D9: Germany | E9: 97881 | F9: 42064 | G9: 2 | H9: Female | I9: user25@example.com
A10: EMP1009 | B10: Chris Lee | C10: HR | D10: UK | E10: 91846 | F10: 42071 | G10: 2 | H10: Male | I10: user153@example.com
A11: EMP1010 | B11: Sam Wilson | C11: Finance | D11: UK | E11: 64247 | F11: 42078 | G11: 1 | H11: Female | I11: user18@example.com
A12: EMP1011 | B12: Sam Wilson | C12: IT | D12: USA | E12: 91180 | F12: 42085 | G12: 5 | H12: Male | I12: user1@example.com
A13: EMP1012 | B13: Bob Johnson | C13: Sales | D13: India | E13: 96418 | F13: 42092 | G13: 5 | H13: Male | I13: user106@example.com
... A142: EMP1149 | B142: Sam Wilson | C142: Marketing | D142: India | E142: 98475 | F142: 43051 | G142: 5 | H142: Other | I142: user30@example.com

Sheet VLookup
A1: Employee Id | B1: Name | C1: Department | D1: Country | E1: Salary | F1: Date Of Joining | G1: Performance Rating | H1: Gender | I1: Email
A2: EMP1001 | B2: =VLOOKUP($A2,Cleaned!$A$2:$I$142,2,FALSE) -> Eve Adams | C2: =VLOOKUP($A2,Cleaned!$A$2:$I$142,3,FALSE) -> HR | D2: =VLOOKUP($A2,Cleaned!$A$2:$I$142,4,FALSE) -> Germany | E2: =VLOOKUP($A2,Cleaned!$A$2:$I$142,5,FALSE) -> 54255 | F2: =VLOOKUP($A2,Cleaned!$A$2:$I$142,6,FALSE) -> 42015 | G2: =VLOOKUP($A2,Cleaned!$A$2:$I$142,7,FALSE) -> 1 | H2: =VLOOKUP($A2,Cleaned!$A$2:$I$142,8,FALSE) -> Other | I2: =VLOOKUP($A2,Cleaned!$A$2:$I$142,9,FALSE) -> user106@example.com
A3: EMP1002 | B3: =VLOOKUP($A3,Cleaned!$A$2:$I$142,2,FALSE) -> Alice Brown | C3: =VLOOKUP($A3,Cleaned!$A$2:$I$142,3,FALSE) -> Finance | D3: =VLOOKUP($A3,Cleaned!$A$2:$I$142,4,FALSE) -> Germany | E3: =VLOOKUP($A3,Cleaned!$A$2:$I$142,5,FALSE) -> 63184 | F3: =VLOOKUP($A3,Cleaned!$A$2:$I$142,6,FALSE) -> 42022 | G3: =VLOOKUP($A3,Cleaned!$A$2:$I$142,7,FALSE) -> 2 | H3: =VLOOKUP($A3,Cleaned!$A$2:$I$142,8,FALSE) -> Female | I3: =VLOOKUP($A3,Cleaned!$A$2:$I$142,9,FALSE) -> user176@example.com
A4: EMP1003 | B4: =VLOOKUP($A4,Cleaned!$A$2:$I$142,2,FALSE) -> John Doe | C4: =VLOOKUP($A4,Cleaned!$A$2:$I$142,3,FALSE) -> Sales | D4: =VLOOKUP($A4,Cleaned!$A$2:$I$142,4,FALSE) -> USA | E4: =VLOOKUP($A4,Cleaned!$A$2:$I$142,5,FALSE) -> 94406 | F4: =VLOOKUP($A4,Cleaned!$A$2:$I$142,6,FALSE) -> 42029 | G4: =VLOOKUP($A4,Cleaned!$A$2:$I$142,7,FALSE) -> 1 | H4: =VLOOKUP($A4,Cleaned!$A$2:$I$142,8,FALSE) -> Male | I4: =VLOOKUP($A4,Cleaned!$A$2:$I$142,9,FALSE) -> user168@example.com
A5: EMP1004 | B5: =VLOOKUP($A5,Cleaned!$A$2:$I$142,2,FALSE) -> Jane Smith | C5: =VLOOKUP($A5,Cleaned!$A$2:$I$142,3,FALSE) -> Sales | D5: =VLOOKUP($A5,Cleaned!$A$2:$I$142,4,FALSE) -> Germany | E5: =VLOOKUP($A5,Cleaned!$A$2:$I$142,5,FALSE) -> 64120 | F5: =VLOOKUP($A5,Cleaned!$A$2:$I$142,6,FALSE) -> 42036 | G5: =VLOOKUP($A5,Cleaned!$A$2:$I$142,7,FALSE) -> 1 | H5: =VLOOKUP($A5,Cleaned!$A$2:$I$142,8,FALSE) -> Male | I5: =VLOOKUP($A5,Cleaned!$A$2:$I$142,9,FALSE) -> user49@example.com
A6: EMP1005 | B6: =VLOOKUP($A6,Cleaned!$A$2:$I$142,2,FALSE) -> Alice Brown | C6: =VLOOKUP($A6,Cleaned!$A$2:$I$142,3,FALSE) -> IT | D6: =VLOOKUP($A6,Cleaned!$A$2:$I$142,4,FALSE) -> India | E6: =VLOOKUP($A6,Cleaned!$A$2:$I$142,5,FALSE) -> 78421 | F6: =VLOOKUP($A6,Cleaned!$A$2:$I$142,6,FALSE) -> 42043 | G6: =VLOOKUP($A6,Cleaned!$A$2:$I$142,7,FALSE) -> 2 | H6: =VLOOKUP($A6,Cleaned!$A$2:$I$142,8,FALSE) -> Female | I6: =VLOOKUP($A6,Cleaned!$A$2:$I$142,9,FALSE) -> user24@example.com
A7: EMP1006 | B7: =VLOOKUP($A7,Cleaned!$A$2:$I$142,2,FALSE) -> Sam Wilson | C7: =VLOOKUP($A7,Cleaned!$A$2:$I$142,3,FALSE) -> Sales | D7: =VLOOKUP($A7,Cleaned!$A$2:$I$142,4,FALSE) -> India | E7: =VLOOKUP($A7,Cleaned!$A$2:$I$142,5,FALSE) -> 67721 | F7: =VLOOKUP($A7,Cleaned!$A$2:$I$142,6,FALSE) -> 42050 | G7: =VLOOKUP($A7,Cleaned!$A$2:$I$142,7,FALSE) -> 2 | H7: =VLOOKUP($A7,Cleaned!$A$2:$I$142,8,FALSE) -> Male | I7: =VLOOKUP($A7,Cleaned!$A$2:$I$142,9,FALSE) -> user168@example.com
A8: EMP1007 | B8: =VLOOKUP($A8,Cleaned!$A$2:$I$142,2,FALSE) -> Chris Lee | C8: =VLOOKUP($A8,Cleaned!$A$2:$I$142,3,FALSE) -> Marketing | D8: =VLOOKUP($A8,Cleaned!$A$2:$I$142,4,FALSE) -> India | E8: =VLOOKUP($A8,Cleaned!$A$2:$I$142,5,FALSE) -> 35364 | F8: =VLOOKUP($A8,Cleaned!$A$2:$I$142,6,FALSE) -> 42057 | G8: =VLOOKUP($A8,Cleaned!$A$2:$I$142,7,FALSE) -> 2 | H8: =VLOOKUP($A8,Cleaned!$A$2:$I$142,8,FALSE) -> Other | I8: =VLOOKUP($A8,Cleaned!$A$2:$I$142,9,FALSE) -> user26@example.com
A9: EMP1008 | B9: =VLOOKUP($A9,Cleaned!$A$2:$I$142,2,FALSE) -> Alice Brown | C9: =VLOOKUP($A9,Cleaned!$A$2:$I$142,3,FALSE) -> IT | D9: =VLOOKUP($A9,Cleaned!$A$2:$I$142,4,FALSE) -> Germany | E9: =VLOOKUP($A9,Cleaned!$A$2:$I$142,5,FALSE) -> 97881 | F9: =VLOOKUP($A9,Cleaned!$A$2:$I$142,6,FALSE) -> 42064 | G9: =VLOOKUP($A9,Cleaned!$A$2:$I$142,7,FALSE) -> 2 | H9: =VLOOKUP($A9,Cleaned!$A$2:$I$142,8,FALSE) -> Female | I9: =VLOOKUP($A9,Cleaned!$A$2:$I$142,9,FALSE) -> user25@example.com
A10: EMP1009 | B10: =VLOOKUP($A10,Cleaned!$A$2:$I$142,2,FALSE) -> Chris Lee | C10: =VLOOKUP($A10,Cleaned!$A$2:$I$142,3,FALSE) -> HR | D10: =VLOOKUP($A10,Cleaned!$A$2:$I$142,4,FALSE) -> UK | E10: =VLOOKUP($A10,Cleaned!$A$2:$I$142,5,FALSE) -> 91846 | F10: =VLOOKUP($A10,Cleaned!$A$2:$I$142,6,FALSE) -> 42071 | G10: =VLOOKUP($A10,Cleaned!$A$2:$I$142,7,FALSE) -> 2 | H10: =VLOOKUP($A10,Cleaned!$A$2:$I$142,8,FALSE) -> Male | I10: =VLOOKUP($A10,Cleaned!$A$2:$I$142,9,FALSE) -> user153@example.com
A11: EMP1010 | B11: =VLOOKUP($A11,Cleaned!$A$2:$I$142,2,FALSE) -> Sam Wilson | C11: =VLOOKUP($A11,Cleaned!$A$2:$I$142,3,FALSE) -> Finance | D11: =VLOOKUP($A11,Cleaned!$A$2:$I$142,4,FALSE) -> UK | E11: =VLOOKUP($A11,Cleaned!$A$2:$I$142,5,FALSE) -> 64247 | F11: =VLOOKUP($A11,Cleaned!$A$2:$I$142,6,FALSE) -> 42078 | G11: =VLOOKUP($A11,Cleaned!$A$2:$I$142,7,FALSE) -> 1 | H11: =VLOOKUP($A11,Cleaned!$A$2:$I$142,8,FALSE) -> Female | I11: =VLOOKUP($A11,Cleaned!$A$2:$I$142,9,FALSE) -> user18@example.com
A12: EMP1011 | B12: =VLOOKUP($A12,Cleaned!$A$2:$I$142,2,FALSE) -> Sam Wilson | C12: =VLOOKUP($A12,Cleaned!$A$2:$I$142,3,FALSE) -> IT | D12: =VLOOKUP($A12,Cleaned!$A$2:$I$142,4,FALSE) -> USA | E12: =VLOOKUP($A12,Cleaned!$A$2:$I$142,5,FALSE) -> 91180 | F12: =VLOOKUP($A12,Cleaned!$A$2:$I$142,6,FALSE) -> 42085 | G12: =VLOOKUP($A12,Cleaned!$A$2:$I$142,7,FALSE) -> 5 | H12: =VLOOKUP($A12,Cleaned!$A$2:$I$142,8,FALSE) -> Male | I12: =VLOOKUP($A12,Cleaned!$A$2:$I$142,9,FALSE) -> user1@example.com
A13: EMP1012 | B13: =VLOOKUP($A13,Cleaned!$A$2:$I$142,2,FALSE) -> Bob Johnson | C13: =VLOOKUP($A13,Cleaned!$A$2:$I$142,3,FALSE) -> Sales | D13: =VLOOKUP($A13,Cleaned!$A$2:$I$142,4,FALSE) -> India | E13: =VLOOKUP($A13,Cleaned!$A$2:$I$142,5,FALSE) -> 96418 | F13: =VLOOKUP($A13,Cleaned!$A$2:$I$142,6,FALSE) -> 42092 | G13: =VLOOKUP($A13,Cleaned!$A$2:$I$142,7,FALSE) -> 5 | H13: =VLOOKUP($A13,Cleaned!$A$2:$I$142,8,FALSE) -> Male | I13: =VLOOKUP($A13,Cleaned!$A$2:$I$142,9,FALSE) -> user106@example.com
... A142: EMP1141 | B142: =VLOOKUP($A142,Cleaned!$A$2:$I$142,2,FALSE) -> Jane Smith | C142: =VLOOKUP($A142,Cleaned!$A$2:$I$142,3,FALSE) -> Marketing | D142: =VLOOKUP($A142,Cleaned!$A$2:$I$142,4,FALSE) -> USA | E142: =VLOOKUP($A142,Cleaned!$A$2:$I$142,5,FALSE) -> 66882 | F142: =VLOOKUP($A142,Cleaned!$A$2:$I$142,6,FALSE) -> 42995 | G142: =VLOOKUP($A142,Cleaned!$A$2:$I$142,7,FALSE) -> 5 | H142: =VLOOKUP($A142,Cleaned!$A$2:$I$142,8,FALSE) -> Other | I142: =VLOOKUP($A142,Cleaned!$A$2:$I$142,9,FALSE) -> user103@example.com
